Workbook
Name IncomeCats: 'Setup'!$B$12:$B$21
Name ExpenseCats: 'Setup'!$E$12:$E$31
Name PlanMonth: 'Setup'!$C$8
Name Cur: 'Setup'!$C$7

Sheet Start Here
B2: Life Planner
B3: Budget • Tasks • Habits • Goals • Meals • Cleaning — Google Sheets & Excel
B6: 1. Setup | C6: Type your name, currency symbol, the month you are planning and your own budget categories. Two minutes, once.
B7: 2. Money Log | C7: The only place you type money. One row per income or expense. Budget, Annual, Savings and Dashboard update themselves.
B8: 3. Budget | C8: Type your planned amount per category. Actual, difference and "safe to spend per day" are calculated for the month chosen in Setup.
B9: 4. Annual | C9: All 12 months side by side, built from the Money Log. Nothing to type.
B10: 5. Savings & Debt | C10: Up to 12 savings goals and 12 debts with live progress bars.
B11: 6. Tasks | C11: 100 tasks with category, due date, priority and status. Open tasks appear on the Dashboard, soonest first.
B12: 7. Habits | C12: 20 habits x 31 days. Type x on the days you did it; streak, total and month score are automatic.
B13: 8. Cleaning | C13: Daily to yearly chores. Type the date you last did it; the next due date and status are calculated.
B14: 9. Goals | C14: 10 goals with why, reward, five dated steps and a progress bar.
B15: 10. Week Plan | C15: Plan your week by the hour, from 6:00 to 22:00.
B16: 11. Meals | C16: Plan breakfast, lunch, dinner and snacks for the week, with a grocery list by aisle.
B17: 12. Calendar | C17: Choose a month: every day shows how many open tasks are due.
... B22: Oakfold | C22: Personal use. Not financial advice.

Sheet Dashboard
B2: Dashboard
B3: =IF('Setup'!C6="","Your month at a glance","Hi "&'Setup'!C6&" — your month at a glance")
B5: =PlanMonth
B6: Income | E6: Expenses | H6: Balance
B7: =Cur&TEXT('Budget'!D42,"#,##0.00") | E7: =Cur&TEXT('Budget'!D43,"#,##0.00") | H7: =IF('Budget'!D44<0,"-",)&Cur&TEXT(ABS('Budget'!D44),"#,##0.00")
B9: Safe to spend / day | C9: =IF('Budget'!D47="","",Cur&TEXT('Budget'!D47,"#,##0.00")) | E9: Next tasks | F9: Due | H9: Habits this month | I9: Score
B10: Total saved | C10: =Cur&TEXT('Savings & Debt'!C36,"#,##0.00") | E10: =IFERROR(INDEX('Tasks'!$B$7:$B$106,MATCH(SMALL('Tasks'!$I$7:$I$106,1),'Tasks'!$I$7:$I$106,0)),"") | F10: =IFERROR(INT(SMALL('Tasks'!$I$7:$I$106,1)),"") | H10: =IF('Habits'!B7="","",'Habits'!B7) | I10: =IF('Habits'!B7="","",'Habits'!AI7)
B11: Debt remaining | C11: =Cur&TEXT('Savings & Debt'!C37,"#,##0.00") | E11: =IFERROR(INDEX('Tasks'!$B$7:$B$106,MATCH(SMALL('Tasks'!$I$7:$I$106,2),'Tasks'!$I$7:$I$106,0)),"") | F11: =IFERROR(INT(SMALL('Tasks'!$I$7:$I$106,2)),"") | H11: =IF('Habits'!B8="","",'Habits'!B8) | I11: =IF('Habits'!B8="","",'Habits'!AI8)
E12: =IFERROR(INDEX('Tasks'!$B$7:$B$106,MATCH(SMALL('Tasks'!$I$7:$I$106,3),'Tasks'!$I$7:$I$106,0)),"") | F12: =IFERROR(INT(SMALL('Tasks'!$I$7:$I$106,3)),"") | H12: =IF('Habits'!B9="","",'Habits'!B9) | I12: =IF('Habits'!B9="","",'Habits'!AI9)
B13: Top spending | C13: Actual | E13: =IFERROR(INDEX('Tasks'!$B$7:$B$106,MATCH(SMALL('Tasks'!$I$7:$I$106,4),'Tasks'!$I$7:$I$106,0)),"") | F13: =IFERROR(INT(SMALL('Tasks'!$I$7:$I$106,4)),"") | H13: =IF('Habits'!B10="","",'Habits'!B10) | I13: =IF('Habits'!B10="","",'Habits'!AI10)
B14: =IFERROR(INDEX('Budget'!$B$21:$B$40,MATCH(LARGE('Budget'!$H$21:$H$40,1),'Budget'!$H$21:$H$40,0)),"") | C14: =IFERROR(INDEX('Budget'!$D$21:$D$40,MATCH(LARGE('Budget'!$H$21:$H$40,1),'Budget'!$H$21:$H$40,0)),"") | E14: =IFERROR(INDEX('Tasks'!$B$7:$B$106,MATCH(SMALL('Tasks'!$I$7:$I$106,5),'Tasks'!$I$7:$I$106,0)),"") | F14: =IFERROR(INT(SMALL('Tasks'!$I$7:$I$106,5)),"") | H14: =IF('Habits'!B11="","",'Habits'!B11) | I14: =IF('Habits'!B11="","",'Habits'!AI11)
B15: =IFERROR(INDEX('Budget'!$B$21:$B$40,MATCH(LARGE('Budget'!$H$21:$H$40,2),'Budget'!$H$21:$H$40,0)),"") | C15: =IFERROR(INDEX('Budget'!$D$21:$D$40,MATCH(LARGE('Budget'!$H$21:$H$40,2),'Budget'!$H$21:$H$40,0)),"") | E15: =IFERROR(INDEX('Tasks'!$B$7:$B$106,MATCH(SMALL('Tasks'!$I$7:$I$106,6),'Tasks'!$I$7:$I$106,0)),"") | F15: =IFERROR(INT(SMALL('Tasks'!$I$7:$I$106,6)),"") | H15: =IF('Habits'!B12="","",'Habits'!B12) | I15: =IF('Habits'!B12="","",'Habits'!AI12)
B16: =IFERROR(INDEX('Budget'!$B$21:$B$40,MATCH(LARGE('Budget'!$H$21:$H$40,3),'Budget'!$H$21:$H$40,0)),"") | C16: =IFERROR(INDEX('Budget'!$D$21:$D$40,MATCH(LARGE('Budget'!$H$21:$H$40,3),'Budget'!$H$21:$H$40,0)),"") | E16: =IFERROR(INDEX('Tasks'!$B$7:$B$106,MATCH(SMALL('Tasks'!$I$7:$I$106,7),'Tasks'!$I$7:$I$106,0)),"") | F16: =IFERROR(INT(SMALL('Tasks'!$I$7:$I$106,7)),"") | H16: =IF('Habits'!B13="","",'Habits'!B13) | I16: =IF('Habits'!B13="","",'Habits'!AI13)
B17: =IFERROR(INDEX('Budget'!$B$21:$B$40,MATCH(LARGE('Budget'!$H$21:$H$40,4),'Budget'!$H$21:$H$40,0)),"") | C17: =IFERROR(INDEX('Budget'!$D$21:$D$40,MATCH(LARGE('Budget'!$H$21:$H$40,4),'Budget'!$H$21:$H$40,0)),"") | E17: =IFERROR(INDEX('Tasks'!$B$7:$B$106,MATCH(SMALL('Tasks'!$I$7:$I$106,8),'Tasks'!$I$7:$I$106,0)),"") | F17: =IFERROR(INT(SMALL('Tasks'!$I$7:$I$106,8)),"") | H17: =IF('Habits'!B14="","",'Habits'!B14) | I17: =IF('Habits'!B14="","",'Habits'!AI14)
B18: =IFERROR(INDEX('Budget'!$B$21:$B$40,MATCH(LARGE('Budget'!$H$21:$H$40,5),'Budget'!$H$21:$H$40,0)),"") | C18: =IFERROR(INDEX('Budget'!$D$21:$D$40,MATCH(LARGE('Budget'!$H$21:$H$40,5),'Budget'!$H$21:$H$40,0)),"")
B20: Meals today | E20: Cleaning due | F20: Status | H20: Savings goals | I20: Progress
B21: Breakfast | C21: =INDEX('Meals'!$C$7:$I$7,WEEKDAY(TODAY(),2)) | E21: {=IFERROR(INDEX('Cleaning'!$B$7:$B$46,SMALL(IF('Cleaning'!$G$7:$G$46<>"Upcoming",IF('Cleaning'!$G$7:$G$46<>"",ROW('Cleaning'!$G$7:$G$46)-6)),1)),"")} | F21: {=IFERROR(INDEX('Cleaning'!$G$7:$G$46,SMALL(IF('Cleaning'!$G$7:$G$46<>"Upcoming",IF('Cleaning'!$G$7:$G$46<>"",ROW('Cleaning'!$G$7:$G$46)-6)),1)),"")} | H21: =IF('Savings & Debt'!B7="","",'Savings & Debt'!B7) | I21: =IF('Savings & Debt'!B7="","",'Savings & Debt'!F7)
B22: Lunch | C22: =INDEX('Meals'!$C$8:$I$8,WEEKDAY(TODAY(),2)) | E22: {=IFERROR(INDEX('Cleaning'!$B$7:$B$46,SMALL(IF('Cleaning'!$G$7:$G$46<>"Upcoming",IF('Cleaning'!$G$7:$G$46<>"",ROW('Cleaning'!$G$7:$G$46)-6)),2)),"")} | F22: {=IFERROR(INDEX('Cleaning'!$G$7:$G$46,SMALL(IF('Cleaning'!$G$7:$G$46<>"Upcoming",IF('Cleaning'!$G$7:$G$46<>"",ROW('Cleaning'!$G$7:$G$46)-6)),2)),"")} | H22: =IF('Savings & Debt'!B8="","",'Savings & Debt'!B8) | I22: =IF('Savings & Debt'!B8="","",'Savings & Debt'!F8)
B23: Dinner | C23: =INDEX('Meals'!$C$9:$I$9,WEEKDAY(TODAY(),2)) | E23: {=IFERROR(INDEX('Cleaning'!$B$7:$B$46,SMALL(IF('Cleaning'!$G$7:$G$46<>"Upcoming",IF('Cleaning'!$G$7:$G$46<>"",ROW('Cleaning'!$G$7:$G$46)-6)),3)),"")} | F23: {=IFERROR(INDEX('Cleaning'!$G$7:$G$46,SMALL(IF('Cleaning'!$G$7:$G$46<>"Upcoming",IF('Cleaning'!$G$7:$G$46<>"",ROW('Cleaning'!$G$7:$G$46)-6)),3)),"")} | H23: =IF('Savings & Debt'!B9="","",'Savings & Debt'!B9) | I23: =IF('Savings & Debt'!B9="","",'Savings & Debt'!F9)
B24: Snacks | C24: =INDEX('Meals'!$C$10:$I$10,WEEKDAY(TODAY(),2)) | E24: {=IFERROR(INDEX('Cleaning'!$B$7:$B$46,SMALL(IF('Cleaning'!$G$7:$G$46<>"Upcoming",IF('Cleaning'!$G$7:$G$46<>"",ROW('Cleaning'!$G$7:$G$46)-6)),4)),"")} | F24: {=IFERROR(INDEX('Cleaning'!$G$7:$G$46,SMALL(IF('Cleaning'!$G$7:$G$46<>"Upcoming",IF('Cleaning'!$G$7:$G$46<>"",ROW('Cleaning'!$G$7:$G$46)-6)),4)),"")} | H24: =IF('Savings & Debt'!B10="","",'Savings & Debt'!B10) | I24: =IF('Savings & Debt'!B10="","",'Savings & Debt'!F10)
E25: {=IFERROR(INDEX('Cleaning'!$B$7:$B$46,SMALL(IF('Cleaning'!$G$7:$G$46<>"Upcoming",IF('Cleaning'!$G$7:$G$46<>"",ROW('Cleaning'!$G$7:$G$46)-6)),5)),"")} | F25: {=IFERROR(INDEX('Cleaning'!$G$7:$G$46,SMALL(IF('Cleaning'!$G$7:$G$46<>"Upcoming",IF('Cleaning'!$G$7:$G$46<>"",ROW('Cleaning'!$G$7:$G$46)-6)),5)),"")} | H25: =IF('Savings & Debt'!B11="","",'Savings & Debt'!B11) | I25: =IF('Savings & Debt'!B11="","",'Savings & Debt'!F11)
E26: {=IFERROR(INDEX('Cleaning'!$B$7:$B$46,SMALL(IF('Cleaning'!$G$7:$G$46<>"Upcoming",IF('Cleaning'!$G$7:$G$46<>"",ROW('Cleaning'!$G$7:$G$46)-6)),6)),"")} | F26: {=IFERROR(INDEX('Cleaning'!$G$7:$G$46,SMALL(IF('Cleaning'!$G$7:$G$46<>"Upcoming",IF('Cleaning'!$G$7:$G$46<>"",ROW('Cleaning'!$G$7:$G$46)-6)),6)),"")} | H26: =IF('Savings & Debt'!B12="","",'Savings & Debt'!B12) | I26: =IF('Savings & Debt'!B12="","",'Savings & Debt'!F12)

Sheet Setup
B2: Setup
B3: Fill the white cells once. Everything else follows.
B6: Your name | C6: Alex
B7: Currency symbol | C7: $
B8: Planning month (first day) | C8: 46296
B9: Year | C9: =YEAR(C8)
B11: Income categories | E11: Expense categories
B12: Salary | E12: Rent / Mortgage
B13: Side income | E13: Utilities
B14: Gifts | E14: Groceries
B15: Refunds | E15: Transport
B16: Other income | E16: Insurance
E17: Phone & Internet
E18: Subscriptions
E19: Eating out
E20: Health
E21: Personal care
E22: Clothing
E23: Kids
E24: Pets
E25: Gifts & Events
E26: Entertainment
E27: Savings transfer
E28: Debt payment
E29: Other
B34: Tip: rename any category; every tab picks up the new name.

Sheet Money Log
B2: Money Log
B3: One row per transaction. Choose Income or Expense, then a category.
B6: Date | C6: Type | D6: Category | E6: Amount | F6: Note | G6: Month
B7: 46235 | C7: Expense | D7: Rent / Mortgage | E7: 1150 | F7: Rent | G7: =IF(B7="","",DATE(YEAR(B7),MONTH(B7),1))
B8: 46235 | C8: Income | D8: Salary | E8: 3250 | F8: Payday | G8: =IF(B8="","",DATE(YEAR(B8),MONTH(B8),1))
B9: 46237 | C9: Expense | D9: Groceries | E9: 127 | F9: Weekly shop | G9: =IF(B9="","",DATE(YEAR(B9),MONTH(B9),1))
B10: 46238 | C10: Expense | D10: Health | E10: 24 | G10: =IF(B10="","",DATE(YEAR(B10),MONTH(B10),1))
B11: 46238 | C11: Expense | D11: Transport | E11: 48 | G11: =IF(B11="","",DATE(YEAR(B11),MONTH(B11),1))
B12: 46239 | C12: Expense | D12: Utilities | E12: 96 | G12: =IF(B12="","",DATE(YEAR(B12),MONTH(B12),1))
B13: 46240 | C13: Expense | D13: Phone & Internet | E13: 65 | G13: =IF(B13="","",DATE(YEAR(B13),MONTH(B13),1))
B14: 46241 | C14: Expense | D14: Pets | E14: 58 | G14: =IF(B14="","",DATE(YEAR(B14),MONTH(B14),1))
B15: 46242 | C15: Expense | D15: Eating out | E15: 46 | G15: =IF(B15="","",DATE(YEAR(B15),MONTH(B15),1))
B16: 46243 | C16: Expense | D16: Insurance | E16: 142 | G16: =IF(B16="","",DATE(YEAR(B16),MONTH(B16),1))
B17: 46244 | C17: Expense | D17: Groceries | E17: 84 | F17: Weekly shop | G17: =IF(B17="","",DATE(YEAR(B17),MONTH(B17),1))
B18: 46245 | C18: Expense | D18: Entertainment | E18: 29 | G18: =IF(B18="","",DATE(YEAR(B18),MONTH(B18),1))
B19: 46245 | C19: Expense | D19: Transport | E19: 35 | G19: =IF(B19="","",DATE(YEAR(B19),MONTH(B19),1))
B20: 46246 | C20: Expense | D20: Subscriptions | E20: 38 | G20: =IF(B20="","",DATE(YEAR(B20),MONTH(B20),1))
B21: 46249 | C21: Income | D21: Side income | E21: 340 | G21: =IF(B21="","",DATE(YEAR(B21),MONTH(B21),1))
B22: 46251 | C22: Expense | D22: Groceries | E22: 84 | F22: Weekly shop | G22: =IF(B22="","",DATE(YEAR(B22),MONTH(B22),1))
B23: 46252 | C23: Expense | D23: Transport | E23: 42 | G23: =IF(B23="","",DATE(YEAR(B23),MONTH(B23),1))
B24: 46254 | C24: Expense | D24: Savings transfer | E24: 300 | F24: Emergency fund | G24: =IF(B24="","",DATE(YEAR(B24),MONTH(B24),1))
B25: 46255 | C25: Expense | D25: Debt payment | E25: 250 | F25: Card payment | G25: =IF(B25="","",DATE(YEAR(B25),MONTH(B25),1))
B26: 46258 | C26: Expense | D26: Groceries | E26: 84 | F26: Weekly shop | G26: =IF(B26="","",DATE(YEAR(B26),MONTH(B26),1))
B27: 46259 | C27: Expense | D27: Transport | E27: 48 | G27: =IF(B27="","",DATE(YEAR(B27),MONTH(B27),1))
B28: 46266 | C28: Expense | D28: Rent / Mortgage | E28: 1150 | F28: Rent | G28: =IF(B28="","",DATE(YEAR(B28),MONTH(B28),1))
B29: 46266 | C29: Income | D29: Salary | E29: 3250 | F29: Payday | G29: =IF(B29="","",DATE(YEAR(B29),MONTH(B29),1))
B30: 46268 | C30: Expense | D30: Groceries | E30: 84 | F30: Weekly shop | G30: =IF(B30="","",DATE(YEAR(B30),MONTH(B30),1))
B31: 46269 | C31: Expense | D31: Health | E31: 24 | G31: =IF(B31="","",DATE(YEAR(B31),MONTH(B31),1))
B32: 46269 | C32: Expense | D32: Transport | E32: 42 | G32: =IF(B32="","",DATE(YEAR(B32),MONTH(B32),1))
B33: 46270 | C33: Expense | D33: Utilities | E33: 96 | G33: =IF(B33="","",DATE(YEAR(B33),MONTH(B33),1))
B34: 46271 | C34: Expense | D34: Phone & Internet | E34: 65 | G34: =IF(B34="","",DATE(YEAR(B34),MONTH(B34),1))
B35: 46272 | C35: Expense | D35: Pets | E35: 58 | G35: =IF(B35="","",DATE(YEAR(B35),MONTH(B35),1))
B36: 46273 | C36: Expense | D36: Eating out | E36: 46 | G36: =IF(B36="","",DATE(YEAR(B36),MONTH(B36),1))
B37: 46274 | C37: Expense | D37: Insurance | E37: 142 | G37: =IF(B37="","",DATE(YEAR(B37),MONTH(B37),1))
B38: 46275 | C38: Expense | D38: Groceries | E38: 127 | F38: Weekly shop | G38: =IF(B38="","",DATE(YEAR(B38),MONTH(B38),1))
B39: 46276 | C39: Expense | D39: Entertainment | E39: 29 | G39: =IF(B39="","",DATE(YEAR(B39),MONTH(B39),1))
B40: 46276 | C40: Expense | D40: Transport | E40: 35 | G40: =IF(B40="","",DATE(YEAR(B40),MONTH(B40),1))
B41: 46277 | C41: Expense | D41: Subscriptions | E41: 38 | G41: =IF(B41="","",DATE(YEAR(B41),MONTH(B41),1))
B42: 46280 | C42: Income | D42: Side income | E42: 280 | G42: =IF(B42="","",DATE(YEAR(B42),MONTH(B42),1))
B43: 46282 | C43: Expense | D43: Groceries | E43: 96 | F43: Weekly shop | G43: =IF(B43="","",DATE(YEAR(B43),MONTH(B43),1))
...

Sheet Budget
B2: Monthly Budget
B3: Month shown = Planning month in Setup. Type planned amounts in the white column.
B6: Month | C6: =PlanMonth
B8: Income | C8: Planned | D8: Actual | E8: Difference | F8: Received
B9: =IF('Setup'!B12="","",'Setup'!B12) | C9: 3250 | D9: =IF(B9="","",SUMIFS('Money Log'!$E$7:$E$506,'Money Log'!$D$7:$D$506,B9,'Money Log'!$C$7:$C$506,"Income",'Money Log'!$G$7:$G$506,PlanMonth)) | E9: =IF(B9="","",D9-N(C9)) | F9: =IF(OR(B9="",N(C9)=0),"",D9/C9)
B10: =IF('Setup'!B13="","",'Setup'!B13) | C10: 350 | D10: =IF(B10="","",SUMIFS('Money Log'!$E$7:$E$506,'Money Log'!$D$7:$D$506,B10,'Money Log'!$C$7:$C$506,"Income",'Money Log'!$G$7:$G$506,PlanMonth)) | E10: =IF(B10="","",D10-N(C10)) | F10: =IF(OR(B10="",N(C10)=0),"",D10/C10)
B11: =IF('Setup'!B14="","",'Setup'!B14) | D11: =IF(B11="","",SUMIFS('Money Log'!$E$7:$E$506,'Money Log'!$D$7:$D$506,B11,'Money Log'!$C$7:$C$506,"Income",'Money Log'!$G$7:$G$506,PlanMonth)) | E11: =IF(B11="","",D11-N(C11)) | F11: =IF(OR(B11="",N(C11)=0),"",D11/C11)
B12: =IF('Setup'!B15="","",'Setup'!B15) | D12: =IF(B12="","",SUMIFS('Money Log'!$E$7:$E$506,'Money Log'!$D$7:$D$506,B12,'Money Log'!$C$7:$C$506,"Income",'Money Log'!$G$7:$G$506,PlanMonth)) | E12: =IF(B12="","",D12-N(C12)) | F12: =IF(OR(B12="",N(C12)=0),"",D12/C12)
B13: =IF('Setup'!B16="","",'Setup'!B16) | D13: =IF(B13="","",SUMIFS('Money Log'!$E$7:$E$506,'Money Log'!$D$7:$D$506,B13,'Money Log'!$C$7:$C$506,"Income",'Money Log'!$G$7:$G$506,PlanMonth)) | E13: =IF(B13="","",D13-N(C13)) | F13: =IF(OR(B13="",N(C13)=0),"",D13/C13)
B14: =IF('Setup'!B17="","",'Setup'!B17) | D14: =IF(B14="","",SUMIFS('Money Log'!$E$7:$E$506,'Money Log'!$D$7:$D$506,B14,'Money Log'!$C$7:$C$506,"Income",'Money Log'!$G$7:$G$506,PlanMonth)) | E14: =IF(B14="","",D14-N(C14)) | F14: =IF(OR(B14="",N(C14)=0),"",D14/C14)
B15: =IF('Setup'!B18="","",'Setup'!B18) | D15: =IF(B15="","",SUMIFS('Money Log'!$E$7:$E$506,'Money Log'!$D$7:$D$506,B15,'Money Log'!$C$7:$C$506,"Income",'Money Log'!$G$7:$G$506,PlanMonth)) | E15: =IF(B15="","",D15-N(C15)) | F15: =IF(OR(B15="",N(C15)=0),"",D15/C15)
B16: =IF('Setup'!B19="","",'Setup'!B19) | D16: =IF(B16="","",SUMIFS('Money Log'!$E$7:$E$506,'Money Log'!$D$7:$D$506,B16,'Money Log'!$C$7:$C$506,"Income",'Money Log'!$G$7:$G$506,PlanMonth)) | E16: =IF(B16="","",D16-N(C16)) | F16: =IF(OR(B16="",N(C16)=0),"",D16/C16)
B17: =IF('Setup'!B20="","",'Setup'!B20) | D17: =IF(B17="","",SUMIFS('Money Log'!$E$7:$E$506,'Money Log'!$D$7:$D$506,B17,'Money Log'!$C$7:$C$506,"Income",'Money Log'!$G$7:$G$506,PlanMonth)) | E17: =IF(B17="","",D17-N(C17)) | F17: =IF(OR(B17="",N(C17)=0),"",D17/C17)
B18: =IF('Setup'!B21="","",'Setup'!B21) | D18: =IF(B18="","",SUMIFS('Money Log'!$E$7:$E$506,'Money Log'!$D$7:$D$506,B18,'Money Log'!$C$7:$C$506,"Income",'Money Log'!$G$7:$G$506,PlanMonth)) | E18: =IF(B18="","",D18-N(C18)) | F18: =IF(OR(B18="",N(C18)=0),"",D18/C18)
B20: Expenses | C20: Planned | D20: Actual | E20: Left | F20: Used
B21: =IF('Setup'!E12="","",'Setup'!E12) | C21: 1150 | D21: =IF(B21="","",SUMIFS('Money Log'!$E$7:$E$506,'Money Log'!$D$7:$D$506,B21,'Money Log'!$C$7:$C$506,"Expense",'Money Log'!$G$7:$G$506,PlanMonth)) | E21: =IF(B21="","",N(C21)-D21) | F21: =IF(OR(B21="",N(C21)=0),"",D21/C21) | H21: =IF(OR(B21="",N(D21)=0),"",D21+ROW()/1000000)
B22: =IF('Setup'!E13="","",'Setup'!E13) | C22: 120 | D22: =IF(B22="","",SUMIFS('Money Log'!$E$7:$E$506,'Money Log'!$D$7:$D$506,B22,'Money Log'!$C$7:$C$506,"Expense",'Money Log'!$G$7:$G$506,PlanMonth)) | E22: =IF(B22="","",N(C22)-D22) | F22: =IF(OR(B22="",N(C22)=0),"",D22/C22) | H22: =IF(OR(B22="",N(D22)=0),"",D22+ROW()/1000000)
B23: =IF('Setup'!E14="","",'Setup'!E14) | C23: 450 | D23: =IF(B23="","",SUMIFS('Money Log'!$E$7:$E$506,'Money Log'!$D$7:$D$506,B23,'Money Log'!$C$7:$C$506,"Expense",'Money Log'!$G$7:$G$506,PlanMonth)) | E23: =IF(B23="","",N(C23)-D23) | F23: =IF(OR(B23="",N(C23)=0),"",D23/C23) | H23: =IF(OR(B23="",N(D23)=0),"",D23+ROW()/1000000)
B24: =IF('Setup'!E15="","",'Setup'!E15) | C24: 180 | D24: =IF(B24="","",SUMIFS('Money Log'!$E$7:$E$506,'Money Log'!$D$7:$D$506,B24,'Money Log'!$C$7:$C$506,"Expense",'Money Log'!$G$7:$G$506,PlanMonth)) | E24: =IF(B24="","",N(C24)-D24) | F24: =IF(OR(B24="",N(C24)=0),"",D24/C24) | H24: =IF(OR(B24="",N(D24)=0),"",D24+ROW()/1000000)
B25: =IF('Setup'!E16="","",'Setup'!E16) | C25: 142 | D25: =IF(B25="","",SUMIFS('Money Log'!$E$7:$E$506,'Money Log'!$D$7:$D$506,B25,'Money Log'!$C$7:$C$506,"Expense",'Money Log'!$G$7:$G$506,PlanMonth)) | E25: =IF(B25="","",N(C25)-D25) | F25: =IF(OR(B25="",N(C25)=0),"",D25/C25) | H25: =IF(OR(B25="",N(D25)=0),"",D25+ROW()/1000000)
B26: =IF('Setup'!E17="","",'Setup'!E17) | C26: 65 | D26: =IF(B26="","",SUMIFS('Money Log'!$E$7:$E$506,'Money Log'!$D$7:$D$506,B26,'Money Log'!$C$7:$C$506,"Expense",'Money Log'!$G$7:$G$506,PlanMonth)) | E26: =IF(B26="","",N(C26)-D26) | F26: =IF(OR(B26="",N(C26)=0),"",D26/C26) | H26: =IF(OR(B26="",N(D26)=0),"",D26+ROW()/1000000)
B27: =IF('Setup'!E18="","",'Setup'!E18) | C27: 40 | D27: =IF(B27="","",SUMIFS('Money Log'!$E$7:$E$506,'Money Log'!$D$7:$D$506,B27,'Money Log'!$C$7:$C$506,"Expense",'Money Log'!$G$7:$G$506,PlanMonth)) | E27: =IF(B27="","",N(C27)-D27) | F27: =IF(OR(B27="",N(C27)=0),"",D27/C27) | H27: =IF(OR(B27="",N(D27)=0),"",D27+ROW()/1000000)
B28: =IF('Setup'!E19="","",'Setup'!E19) | C28: 80 | D28: =IF(B28="","",SUMIFS('Money Log'!$E$7:$E$506,'Money Log'!$D$7:$D$506,B28,'Money Log'!$C$7:$C$506,"Expense",'Money Log'!$G$7:$G$506,PlanMonth)) | E28: =IF(B28="","",N(C28)-D28) | F28: =IF(OR(B28="",N(C28)=0),"",D28/C28) | H28: =IF(OR(B28="",N(D28)=0),"",D28+ROW()/1000000)
B29: =IF('Setup'!E20="","",'Setup'!E20) | C29: 40 | D29: =IF(B29="","",SUMIFS('Money Log'!$E$7:$E$506,'Money Log'!$D$7:$D$506,B29,'Money Log'!$C$7:$C$506,"Expense",'Money Log'!$G$7:$G$506,PlanMonth)) | E29: =IF(B29="","",N(C29)-D29) | F29: =IF(OR(B29="",N(C29)=0),"",D29/C29) | H29: =IF(OR(B29="",N(D29)=0),"",D29+ROW()/1000000)
B30: =IF('Setup'!E21="","",'Setup'!E21) | C30: 30 | D30: =IF(B30="","",SUMIFS('Money Log'!$E$7:$E$506,'Money Log'!$D$7:$D$506,B30,'Money Log'!$C$7:$C$506,"Expense",'Money Log'!$G$7:$G$506,PlanMonth)) | E30: =IF(B30="","",N(C30)-D30) | F30: =IF(OR(B30="",N(C30)=0),"",D30/C30) | H30: =IF(OR(B30="",N(D30)=0),"",D30+ROW()/1000000)
B31: =IF('Setup'!E22="","",'Setup'!E22) | C31: 40 | D31: =IF(B31="","",SUMIFS('Money Log'!$E$7:$E$506,'Money Log'!$D$7:$D$506,B31,'Money Log'!$C$7:$C$506,"Expense",'Money Log'!$G$7:$G$506,PlanMonth)) | E31: =IF(B31="","",N(C31)-D31) | F31: =IF(OR(B31="",N(C31)=0),"",D31/C31) | H31: =IF(OR(B31="",N(D31)=0),"",D31+ROW()/1000000)
B32: =IF('Setup'!E23="","",'Setup'!E23) | D32: =IF(B32="","",SUMIFS('Money Log'!$E$7:$E$506,'Money Log'!$D$7:$D$506,B32,'Money Log'!$C$7:$C$506,"Expense",'Money Log'!$G$7:$G$506,PlanMonth)) | E32: =IF(B32="","",N(C32)-D32) | F32: =IF(OR(B32="",N(C32)=0),"",D32/C32) | H32: =IF(OR(B32="",N(D32)=0),"",D32+ROW()/1000000)
B33: =IF('Setup'!E24="","",'Setup'!E24) | C33: 60 | D33: =IF(B33="","",SUMIFS('Money Log'!$E$7:$E$506,'Money Log'!$D$7:$D$506,B33,'Money Log'!$C$7:$C$506,"Expense",'Money Log'!$G$7:$G$506,PlanMonth)) | E33: =IF(B33="","",N(C33)-D33) | F33: =IF(OR(B33="",N(C33)=0),"",D33/C33) | H33: =IF(OR(B33="",N(D33)=0),"",D33+ROW()/1000000)
B34: =IF('Setup'!E25="","",'Setup'!E25) | C34: 50 | D34: =IF(B34="","",SUMIFS('Money Log'!$E$7:$E$506,'Money Log'!$D$7:$D$506,B34,'Money Log'!$C$7:$C$506,"Expense",'Money Log'!$G$7:$G$506,PlanMonth)) | E34: =IF(B34="","",N(C34)-D34) | F34: =IF(OR(B34="",N(C34)=0),"",D34/C34) | H34: =IF(OR(B34="",N(D34)=0),"",D34+ROW()/1000000)
B35: =IF('Setup'!E26="","",'Setup'!E26) | C35: 40 | D35: =IF(B35="","",SUMIFS('Money Log'!$E$7:$E$506,'Money Log'!$D$7:$D$506,B35,'Money Log'!$C$7:$C$506,"Expense",'Money Log'!$G$7:$G$506,PlanMonth)) | E35: =IF(B35="","",N(C35)-D35) | F35: =IF(OR(B35="",N(C35)=0),"",D35/C35) | H35: =IF(OR(B35="",N(D35)=0),"",D35+ROW()/1000000)
B36: =IF('Setup'!E27="","",'Setup'!E27) | C36: 300 | D36: =IF(B36="","",SUMIFS('Money Log'!$E$7:$E$506,'Money Log'!$D$7:$D$506,B36,'Money Log'!$C$7:$C$506,"Expense",'Money Log'!$G$7:$G$506,PlanMonth)) | E36: =IF(B36="","",N(C36)-D36) | F36: =IF(OR(B36="",N(C36)=0),"",D36/C36) | H36: =IF(OR(B36="",N(D36)=0),"",D36+ROW()/1000000)
B37: =IF('Setup'!E28="","",'Setup'!E28) | C37: 250 | D37: =IF(B37="","",SUMIFS('Money Log'!$E$7:$E$506,'Money Log'!$D$7:$D$506,B37,'Money Log'!$C$7:$C$506,"Expense",'Money Log'!$G$7:$G$506,PlanMonth)) | E37: =IF(B37="","",N(C37)-D37) | F37: =IF(OR(B37="",N(C37)=0),"",D37/C37) | H37: =IF(OR(B37="",N(D37)=0),"",D37+ROW()/1000000)
B38: =IF('Setup'!E29="","",'Setup'!E29) | C38: 50 | D38: =IF(B38="","",SUMIFS('Money Log'!$E$7:$E$506,'Money Log'!$D$7:$D$506,B38,'Money Log'!$C$7:$C$506,"Expense",'Money Log'!$G$7:$G$506,PlanMonth)) | E38: =IF(B38="","",N(C38)-D38) | F38: =IF(OR(B38="",N(C38)=0),"",D38/C38) | H38: =IF(OR(B38="",N(D38)=0),"",D38+ROW()/1000000)
B39: =IF('Setup'!E30="","",'Setup'!E30) | D39: =IF(B39="","",SUMIFS('Money Log'!$E$7:$E$506,'Money Log'!$D$7:$D$506,B39,'Money Log'!$C$7:$C$506,"Expense",'Money Log'!$G$7:$G$506,PlanMonth)) | E39: =IF(B39="","",N(C39)-D39) | F39: =IF(OR(B39="",N(C39)=0),"",D39/C39) | H39: =IF(OR(B39="",N(D39)=0),"",D39+ROW()/1000000)
B40: =IF('Setup'!E31="","",'Setup'!E31) | D40: =IF(B40="","",SUMIFS('Money Log'!$E$7:$E$506,'Money Log'!$D$7:$D$506,B40,'Money Log'!$C$7:$C$506,"Expense",'Money Log'!$G$7:$G$506,PlanMonth)) | E40: =IF(B40="","",N(C40)-D40) | F40: =IF(OR(B40="",N(C40)=0),"",D40/C40) | H40: =IF(OR(B40="",N(D40)=0),"",D40+ROW()/1000000)
B42: Total income | D42: =SUM(D9:D18)
B43: Total expenses | D43: =SUM(D21:D40)
B44: Balance | D44: =D42-D43
B45: Planned left to spend | D45: =SUM(C21:C40)-D43
B46: Days left this month | D46: =IF(MONTH(TODAY())=MONTH(PlanMonth),DAY(EOMONTH(PlanMonth,0))-DAY(TODAY())+1,"")
...

Sheet Annual
B2: Annual Overview
B3: Twelve months from the Money Log for the year in Setup. Nothing to type.
C5: =DATE('Setup'!$C$9,1,1) | D5: =DATE('Setup'!$C$9,2,1) | E5: =DATE('Setup'!$C$9,3,1) | F5: =DATE('Setup'!$C$9,4,1) | G5: =DATE('Setup'!$C$9,5,1) | H5: =DATE('Setup'!$C$9,6,1) | I5: =DATE('Setup'!$C$9,7,1) | J5: =DATE('Setup'!$C$9,8,1) | K5: =DATE('Setup'!$C$9,9,1) | L5: =DATE('Setup'!$C$9,10,1) | M5: =DATE('Setup'!$C$9,11,1) | N5: =DATE('Setup'!$C$9,12,1)
B6: Category | C6: Jan | D6: Feb | E6: Mar | F6: Apr | G6: May | H6: Jun | I6: Jul | J6: Aug | K6: Sep | L6: Oct | M6: Nov | N6: Dec | O6: Year
B7: INCOME
B8: =IF('Setup'!B12="","",'Setup'!B12) | C8: =IF($B8="","",SUMIFS('Money Log'!$E$7:$E$506,'Money Log'!$D$7:$D$506,$B8,'Money Log'!$C$7:$C$506,"Income",'Money Log'!$G$7:$G$506,C$5)) | D8: =IF($B8="","",SUMIFS('Money Log'!$E$7:$E$506,'Money Log'!$D$7:$D$506,$B8,'Money Log'!$C$7:$C$506,"Income",'Money Log'!$G$7:$G$506,D$5)) | E8: =IF($B8="","",SUMIFS('Money Log'!$E$7:$E$506,'Money Log'!$D$7:$D$506,$B8,'Money Log'!$C$7:$C$506,"Income",'Money Log'!$G$7:$G$506,E$5)) | F8: =IF($B8="","",SUMIFS('Money Log'!$E$7:$E$506,'Money Log'!$D$7:$D$506,$B8,'Money Log'!$C$7:$C$506,"Income",'Money Log'!$G$7:$G$506,F$5)) | G8: =IF($B8="","",SUMIFS('Money Log'!$E$7:$E$506,'Money Log'!$D$7:$D$506,$B8,'Money Log'!$C$7:$C$506,"Income",'Money Log'!$G$7:$G$506,G$5)) | H8: =IF($B8="","",SUMIFS('Money Log'!$E$7:$E$506,'Money Log'!$D$7:$D$506,$B8,'Money Log'!$C$7:$C$506,"Income",'Money Log'!$G$7:$G$506,H$5)) | I8: =IF($B8="","",SUMIFS('Money Log'!$E$7:$E$506,'Money Log'!$D$7:$D$506,$B8,'Money Log'!$C$7:$C$506,"Income",'Money Log'!$G$7:$G$506,I$5)) | J8: =IF($B8="","",SUMIFS('Money Log'!$E$7:$E$506,'Money Log'!$D$7:$D$506,$B8,'Money Log'!$C$7:$C$506,"Income",'Money Log'!$G$7:$G$506,J$5)) | ... N8: =IF($B8="","",SUMIFS('Money Log'!$E$7:$E$506,'Money Log'!$D$7:$D$506,$B8,'Money Log'!$C$7:$C$506,"Income",'Money Log'!$G$7:$G$506,N$5)) | O8: =IF($B8="","",SUM(C8:N8))
B9: =IF('Setup'!B13="","",'Setup'!B13) | C9: =IF($B9="","",SUMIFS('Money Log'!$E$7:$E$506,'Money Log'!$D$7:$D$506,$B9,'Money Log'!$C$7:$C$506,"Income",'Money Log'!$G$7:$G$506,C$5)) | D9: =IF($B9="","",SUMIFS('Money Log'!$E$7:$E$506,'Money Log'!$D$7:$D$506,$B9,'Money Log'!$C$7:$C$506,"Income",'Money Log'!$G$7:$G$506,D$5)) | E9: =IF($B9="","",SUMIFS('Money Log'!$E$7:$E$506,'Money Log'!$D$7:$D$506,$B9,'Money Log'!$C$7:$C$506,"Income",'Money Log'!$G$7:$G$506,E$5)) | F9: =IF($B9="","",SUMIFS('Money Log'!$E$7:$E$506,'Money Log'!$D$7:$D$506,$B9,'Money Log'!$C$7:$C$506,"Income",'Money Log'!$G$7:$G$506,F$5)) | G9: =IF($B9="","",SUMIFS('Money Log'!$E$7:$E$506,'Money Log'!$D$7:$D$506,$B9,'Money Log'!$C$7:$C$506,"Income",'Money Log'!$G$7:$G$506,G$5)) | H9: =IF($B9="","",SUMIFS('Money Log'!$E$7:$E$506,'Money Log'!$D$7:$D$506,$B9,'Money Log'!$C$7:$C$506,"Income",'Money Log'!$G$7:$G$506,H$5)) | I9: =IF($B9="","",SUMIFS('Money Log'!$E$7:$E$506,'Money Log'!$D$7:$D$506,$B9,'Money Log'!$C$7:$C$506,"Income",'Money Log'!$G$7:$G$506,I$5)) | J9: =IF($B9="","",SUMIFS('Money Log'!$E$7:$E$506,'Money Log'!$D$7:$D$506,$B9,'Money Log'!$C$7:$C$506,"Income",'Money Log'!$G$7:$G$506,J$5)) | ... N9: =IF($B9="","",SUMIFS('Money Log'!$E$7:$E$506,'Money Log'!$D$7:$D$506,$B9,'Money Log'!$C$7:$C$506,"Income",'Money Log'!$G$7:$G$506,N$5)) | O9: =IF($B9="","",SUM(C9:N9))
B10: =IF('Setup'!B14="","",'Setup'!B14) | C10: =IF($B10="","",SUMIFS('Money Log'!$E$7:$E$506,'Money Log'!$D$7:$D$506,$B10,'Money Log'!$C$7:$C$506,"Income",'Money Log'!$G$7:$G$506,C$5)) | D10: =IF($B10="","",SUMIFS('Money Log'!$E$7:$E$506,'Money Log'!$D$7:$D$506,$B10,'Money Log'!$C$7:$C$506,"Income",'Money Log'!$G$7:$G$506,D$5)) | E10: =IF($B10="","",SUMIFS('Money Log'!$E$7:$E$506,'Money Log'!$D$7:$D$506,$B10,'Money Log'!$C$7:$C$506,"Income",'Money Log'!$G$7:$G$506,E$5)) | F10: =IF($B10="","",SUMIFS('Money Log'!$E$7:$E$506,'Money Log'!$D$7:$D$506,$B10,'Money Log'!$C$7:$C$506,"Income",'Money Log'!$G$7:$G$506,F$5)) | G10: =IF($B10="","",SUMIFS('Money Log'!$E$7:$E$506,'Money Log'!$D$7:$D$506,$B10,'Money Log'!$C$7:$C$506,"Income",'Money Log'!$G$7:$G$506,G$5)) | H10: =IF($B10="","",SUMIFS('Money Log'!$E$7:$E$506,'Money Log'!$D$7:$D$506,$B10,'Money Log'!$C$7:$C$506,"Income",'Money Log'!$G$7:$G$506,H$5)) | I10: =IF($B10="","",SUMIFS('Money Log'!$E$7:$E$506,'Money Log'!$D$7:$D$506,$B10,'Money Log'!$C$7:$C$506,"Income",'Money Log'!$G$7:$G$506,I$5)) | J10: =IF($B10="","",SUMIFS('Money Log'!$E$7:$E$506,'Money Log'!$D$7:$D$506,$B10,'Money Log'!$C$7:$C$506,"Income",'Money Log'!$G$7:$G$506,J$5)) | ... N10: =IF($B10="","",SUMIFS('Money Log'!$E$7:$E$506,'Money Log'!$D$7:$D$506,$B10,'Money Log'!$C$7:$C$506,"Income",'Money Log'!$G$7:$G$506,N$5)) | O10: =IF($B10="","",SUM(C10:N10))
B11: =IF('Setup'!B15="","",'Setup'!B15) | C11: =IF($B11="","",SUMIFS('Money Log'!$E$7:$E$506,'Money Log'!$D$7:$D$506,$B11,'Money Log'!$C$7:$C$506,"Income",'Money Log'!$G$7:$G$506,C$5)) | D11: =IF($B11="","",SUMIFS('Money Log'!$E$7:$E$506,'Money Log'!$D$7:$D$506,$B11,'Money Log'!$C$7:$C$506,"Income",'Money Log'!$G$7:$G$506,D$5)) | E11: =IF($B11="","",SUMIFS('Money Log'!$E$7:$E$506,'Money Log'!$D$7:$D$506,$B11,'Money Log'!$C$7:$C$506,"Income",'Money Log'!$G$7:$G$506,E$5)) | F11: =IF($B11="","",SUMIFS('Money Log'!$E$7:$E$506,'Money Log'!$D$7:$D$506,$B11,'Money Log'!$C$7:$C$506,"Income",'Money Log'!$G$7:$G$506,F$5)) | G11: =IF($B11="","",SUMIFS('Money Log'!$E$7:$E$506,'Money Log'!$D$7:$D$506,$B11,'Money Log'!$C$7:$C$506,"Income",'Money Log'!$G$7:$G$506,G$5)) | H11: =IF($B11="","",SUMIFS('Money Log'!$E$7:$E$506,'Money Log'!$D$7:$D$506,$B11,'Money Log'!$C$7:$C$506,"Income",'Money Log'!$G$7:$G$506,H$5)) | I11: =IF($B11="","",SUMIFS('Money Log'!$E$7:$E$506,'Money Log'!$D$7:$D$506,$B11,'Money Log'!$C$7:$C$506,"Income",'Money Log'!$G$7:$G$506,I$5)) | J11: =IF($B11="","",SUMIFS('Money Log'!$E$7:$E$506,'Money Log'!$D$7:$D$506,$B11,'Money Log'!$C$7:$C$506,"Income",'Money Log'!$G$7:$G$506,J$5)) | ... N11: =IF($B11="","",SUMIFS('Money Log'!$E$7:$E$506,'Money Log'!$D$7:$D$506,$B11,'Money Log'!$C$7:$C$506,"Income",'Money Log'!$G$7:$G$506,N$5)) | O11: =IF($B11="","",SUM(C11:N11))
B12: =IF('Setup'!B16="","",'Setup'!B16) | C12: =IF($B12="","",SUMIFS('Money Log'!$E$7:$E$506,'Money Log'!$D$7:$D$506,$B12,'Money Log'!$C$7:$C$506,"Income",'Money Log'!$G$7:$G$506,C$5)) | D12: =IF($B12="","",SUMIFS('Money Log'!$E$7:$E$506,'Money Log'!$D$7:$D$506,$B12,'Money Log'!$C$7:$C$506,"Income",'Money Log'!$G$7:$G$506,D$5)) | E12: =IF($B12="","",SUMIFS('Money Log'!$E$7:$E$506,'Money Log'!$D$7:$D$506,$B12,'Money Log'!$C$7:$C$506,"Income",'Money Log'!$G$7:$G$506,E$5)) | F12: =IF($B12="","",SUMIFS('Money Log'!$E$7:$E$506,'Money Log'!$D$7:$D$506,$B12,'Money Log'!$C$7:$C$506,"Income",'Money Log'!$G$7:$G$506,F$5)) | G12: =IF($B12="","",SUMIFS('Money Log'!$E$7:$E$506,'Money Log'!$D$7:$D$506,$B12,'Money Log'!$C$7:$C$506,"Income",'Money Log'!$G$7:$G$506,G$5)) | H12: =IF($B12="","",SUMIFS('Money Log'!$E$7:$E$506,'Money Log'!$D$7:$D$506,$B12,'Money Log'!$C$7:$C$506,"Income",'Money Log'!$G$7:$G$506,H$5)) | I12: =IF($B12="","",SUMIFS('Money Log'!$E$7:$E$506,'Money Log'!$D$7:$D$506,$B12,'Money Log'!$C$7:$C$506,"Income",'Money Log'!$G$7:$G$506,I$5)) | J12: =IF($B12="","",SUMIFS('Money Log'!$E$7:$E$506,'Money Log'!$D$7:$D$506,$B12,'Money Log'!$C$7:$C$506,"Income",'Money Log'!$G$7:$G$506,J$5)) | ... N12: =IF($B12="","",SUMIFS('Money Log'!$E$7:$E$506,'Money Log'!$D$7:$D$506,$B12,'Money Log'!$C$7:$C$506,"Income",'Money Log'!$G$7:$G$506,N$5)) | O12: =IF($B12="","",SUM(C12:N12))
B13: =IF('Setup'!B17="","",'Setup'!B17) | C13: =IF($B13="","",SUMIFS('Money Log'!$E$7:$E$506,'Money Log'!$D$7:$D$506,$B13,'Money Log'!$C$7:$C$506,"Income",'Money Log'!$G$7:$G$506,C$5)) | D13: =IF($B13="","",SUMIFS('Money Log'!$E$7:$E$506,'Money Log'!$D$7:$D$506,$B13,'Money Log'!$C$7:$C$506,"Income",'Money Log'!$G$7:$G$506,D$5)) | E13: =IF($B13="","",SUMIFS('Money Log'!$E$7:$E$506,'Money Log'!$D$7:$D$506,$B13,'Money Log'!$C$7:$C$506,"Income",'Money Log'!$G$7:$G$506,E$5)) | F13: =IF($B13="","",SUMIFS('Money Log'!$E$7:$E$506,'Money Log'!$D$7:$D$506,$B13,'Money Log'!$C$7:$C$506,"Income",'Money Log'!$G$7:$G$506,F$5)) | G13: =IF($B13="","",SUMIFS('Money Log'!$E$7:$E$506,'Money Log'!$D$7:$D$506,$B13,'Money Log'!$C$7:$C$506,"Income",'Money Log'!$G$7:$G$506,G$5)) | H13: =IF($B13="","",SUMIFS('Money Log'!$E$7:$E$506,'Money Log'!$D$7:$D$506,$B13,'Money Log'!$C$7:$C$506,"Income",'Money Log'!$G$7:$G$506,H$5)) | I13: =IF($B13="","",SUMIFS('Money Log'!$E$7:$E$506,'Money Log'!$D$7:$D$506,$B13,'Money Log'!$C$7:$C$506,"Income",'Money Log'!$G$7:$G$506,I$5)) | J13: =IF($B13="","",SUMIFS('Money Log'!$E$7:$E$506,'Money Log'!$D$7:$D$506,$B13,'Money Log'!$C$7:$C$506,"Income",'Money Log'!$G$7:$G$506,J$5)) | ... N13: =IF($B13="","",SUMIFS('Money Log'!$E$7:$E$506,'Money Log'!$D$7:$D$506,$B13,'Money Log'!$C$7:$C$506,"Income",'Money Log'!$G$7:$G$506,N$5)) | O13: =IF($B13="","",SUM(C13:N13))
B14: =IF('Setup'!B18="","",'Setup'!B18) | C14: =IF($B14="","",SUMIFS('Money Log'!$E$7:$E$506,'Money Log'!$D$7:$D$506,$B14,'Money Log'!$C$7:$C$506,"Income",'Money Log'!$G$7:$G$506,C$5)) | D14: =IF($B14="","",SUMIFS('Money Log'!$E$7:$E$506,'Money Log'!$D$7:$D$506,$B14,'Money Log'!$C$7:$C$506,"Income",'Money Log'!$G$7:$G$506,D$5)) | E14: =IF($B14="","",SUMIFS('Money Log'!$E$7:$E$506,'Money Log'!$D$7:$D$506,$B14,'Money Log'!$C$7:$C$506,"Income",'Money Log'!$G$7:$G$506,E$5)) | F14: =IF($B14="","",SUMIFS('Money Log'!$E$7:$E$506,'Money Log'!$D$7:$D$506,$B14,'Money Log'!$C$7:$C$506,"Income",'Money Log'!$G$7:$G$506,F$5)) | G14: =IF($B14="","",SUMIFS('Money Log'!$E$7:$E$506,'Money Log'!$D$7:$D$506,$B14,'Money Log'!$C$7:$C$506,"Income",'Money Log'!$G$7:$G$506,G$5)) | H14: =IF($B14="","",SUMIFS('Money Log'!$E$7:$E$506,'Money Log'!$D$7:$D$506,$B14,'Money Log'!$C$7:$C$506,"Income",'Money Log'!$G$7:$G$506,H$5)) | I14: =IF($B14="","",SUMIFS('Money Log'!$E$7:$E$506,'Money Log'!$D$7:$D$506,$B14,'Money Log'!$C$7:$C$506,"Income",'Money Log'!$G$7:$G$506,I$5)) | J14: =IF($B14="","",SUMIFS('Money Log'!$E$7:$E$506,'Money Log'!$D$7:$D$506,$B14,'Money Log'!$C$7:$C$506,"Income",'Money Log'!$G$7:$G$506,J$5)) | ... N14: =IF($B14="","",SUMIFS('Money Log'!$E$7:$E$506,'Money Log'!$D$7:$D$506,$B14,'Money Log'!$C$7:$C$506,"Income",'Money Log'!$G$7:$G$506,N$5)) | O14: =IF($B14="","",SUM(C14:N14))
B15: =IF('Setup'!B19="","",'Setup'!B19) | C15: =IF($B15="","",SUMIFS('Money Log'!$E$7:$E$506,'Money Log'!$D$7:$D$506,$B15,'Money Log'!$C$7:$C$506,"Income",'Money Log'!$G$7:$G$506,C$5)) | D15: =IF($B15="","",SUMIFS('Money Log'!$E$7:$E$506,'Money Log'!$D$7:$D$506,$B15,'Money Log'!$C$7:$C$506,"Income",'Money Log'!$G$7:$G$506,D$5)) | E15: =IF($B15="","",SUMIFS('Money Log'!$E$7:$E$506,'Money Log'!$D$7:$D$506,$B15,'Money Log'!$C$7:$C$506,"Income",'Money Log'!$G$7:$G$506,E$5)) | F15: =IF($B15="","",SUMIFS('Money Log'!$E$7:$E$506,'Money Log'!$D$7:$D$506,$B15,'Money Log'!$C$7:$C$506,"Income",'Money Log'!$G$7:$G$506,F$5)) | G15: =IF($B15="","",SUMIFS('Money Log'!$E$7:$E$506,'Money Log'!$D$7:$D$506,$B15,'Money Log'!$C$7:$C$506,"Income",'Money Log'!$G$7:$G$506,G$5)) | H15: =IF($B15="","",SUMIFS('Money Log'!$E$7:$E$506,'Money Log'!$D$7:$D$506,$B15,'Money Log'!$C$7:$C$506,"Income",'Money Log'!$G$7:$G$506,H$5)) | I15: =IF($B15="","",SUMIFS('Money Log'!$E$7:$E$506,'Money Log'!$D$7:$D$506,$B15,'Money Log'!$C$7:$C$506,"Income",'Money Log'!$G$7:$G$506,I$5)) | J15: =IF($B15="","",SUMIFS('Money Log'!$E$7:$E$506,'Money Log'!$D$7:$D$506,$B15,'Money Log'!$C$7:$C$506,"Income",'Money Log'!$G$7:$G$506,J$5)) | ... N15: =IF($B15="","",SUMIFS('Money Log'!$E$7:$E$506,'Money Log'!$D$7:$D$506,$B15,'Money Log'!$C$7:$C$506,"Income",'Money Log'!$G$7:$G$506,N$5)) | O15: =IF($B15="","",SUM(C15:N15))
B16: =IF('Setup'!B20="","",'Setup'!B20) | C16: =IF($B16="","",SUMIFS('Money Log'!$E$7:$E$506,'Money Log'!$D$7:$D$506,$B16,'Money Log'!$C$7:$C$506,"Income",'Money Log'!$G$7:$G$506,C$5)) | D16: =IF($B16="","",SUMIFS('Money Log'!$E$7:$E$506,'Money Log'!$D$7:$D$506,$B16,'Money Log'!$C$7:$C$506,"Income",'Money Log'!$G$7:$G$506,D$5)) | E16: =IF($B16="","",SUMIFS('Money Log'!$E$7:$E$506,'Money Log'!$D$7:$D$506,$B16,'Money Log'!$C$7:$C$506,"Income",'Money Log'!$G$7:$G$506,E$5)) | F16: =IF($B16="","",SUMIFS('Money Log'!$E$7:$E$506,'Money Log'!$D$7:$D$506,$B16,'Money Log'!$C$7:$C$506,"Income",'Money Log'!$G$7:$G$506,F$5)) | G16: =IF($B16="","",SUMIFS('Money Log'!$E$7:$E$506,'Money Log'!$D$7:$D$506,$B16,'Money Log'!$C$7:$C$506,"Income",'Money Log'!$G$7:$G$506,G$5)) | H16: =IF($B16="","",SUMIFS('Money Log'!$E$7:$E$506,'Money Log'!$D$7:$D$506,$B16,'Money Log'!$C$7:$C$506,"Income",'Money Log'!$G$7:$G$506,H$5)) | I16: =IF($B16="","",SUMIFS('Money Log'!$E$7:$E$506,'Money Log'!$D$7:$D$506,$B16,'Money Log'!$C$7:$C$506,"Income",'Money Log'!$G$7:$G$506,I$5)) | J16: =IF($B16="","",SUMIFS('Money Log'!$E$7:$E$506,'Money Log'!$D$7:$D$506,$B16,'Money Log'!$C$7:$C$506,"Income",'Money Log'!$G$7:$G$506,J$5)) | ... N16: =IF($B16="","",SUMIFS('Money Log'!$E$7:$E$506,'Money Log'!$D$7:$D$506,$B16,'Money Log'!$C$7:$C$506,"Income",'Money Log'!$G$7:$G$506,N$5)) | O16: =IF($B16="","",SUM(C16:N16))
B17: =IF('Setup'!B21="","",'Setup'!B21) | C17: =IF($B17="","",SUMIFS('Money Log'!$E$7:$E$506,'Money Log'!$D$7:$D$506,$B17,'Money Log'!$C$7:$C$506,"Income",'Money Log'!$G$7:$G$506,C$5)) | D17: =IF($B17="","",SUMIFS('Money Log'!$E$7:$E$506,'Money Log'!$D$7:$D$506,$B17,'Money Log'!$C$7:$C$506,"Income",'Money Log'!$G$7:$G$506,D$5)) | E17: =IF($B17="","",SUMIFS('Money Log'!$E$7:$E$506,'Money Log'!$D$7:$D$506,$B17,'Money Log'!$C$7:$C$506,"Income",'Money Log'!$G$7:$G$506,E$5)) | F17: =IF($B17="","",SUMIFS('Money Log'!$E$7:$E$506,'Money Log'!$D$7:$D$506,$B17,'Money Log'!$C$7:$C$506,"Income",'Money Log'!$G$7:$G$506,F$5)) | G17: =IF($B17="","",SUMIFS('Money Log'!$E$7:$E$506,'Money Log'!$D$7:$D$506,$B17,'Money Log'!$C$7:$C$506,"Income",'Money Log'!$G$7:$G$506,G$5)) | H17: =IF($B17="","",SUMIFS('Money Log'!$E$7:$E$506,'Money Log'!$D$7:$D$506,$B17,'Money Log'!$C$7:$C$506,"Income",'Money Log'!$G$7:$G$506,H$5)) | I17: =IF($B17="","",SUMIFS('Money Log'!$E$7:$E$506,'Money Log'!$D$7:$D$506,$B17,'Money Log'!$C$7:$C$506,"Income",'Money Log'!$G$7:$G$506,I$5)) | J17: =IF($B17="","",SUMIFS('Money Log'!$E$7:$E$506,'Money Log'!$D$7:$D$506,$B17,'Money Log'!$C$7:$C$506,"Income",'Money Log'!$G$7:$G$506,J$5)) | ... N17: =IF($B17="","",SUMIFS('Money Log'!$E$7:$E$506,'Money Log'!$D$7:$D$506,$B17,'Money Log'!$C$7:$C$506,"Income",'Money Log'!$G$7:$G$506,N$5)) | O17: =IF($B17="","",SUM(C17:N17))
B18: Total income | C18: =SUM(C8:C17) | D18: =SUM(D8:D17) | E18: =SUM(E8:E17) | F18: =SUM(F8:F17) | G18: =SUM(G8:G17) | H18: =SUM(H8:H17) | I18: =SUM(I8:I17) | J18: =SUM(J8:J17) | ... O18: =SUM(O8:O17)
B20: EXPENSES
B21: =IF('Setup'!E12="","",'Setup'!E12) | C21: =IF($B21="","",SUMIFS('Money Log'!$E$7:$E$506,'Money Log'!$D$7:$D$506,$B21,'Money Log'!$C$7:$C$506,"Expense",'Money Log'!$G$7:$G$506,C$5)) | D21: =IF($B21="","",SUMIFS('Money Log'!$E$7:$E$506,'Money Log'!$D$7:$D$506,$B21,'Money Log'!$C$7:$C$506,"Expense",'Money Log'!$G$7:$G$506,D$5)) | E21: =IF($B21="","",SUMIFS('Money Log'!$E$7:$E$506,'Money Log'!$D$7:$D$506,$B21,'Money Log'!$C$7:$C$506,"Expense",'Money Log'!$G$7:$G$506,E$5)) | F21: =IF($B21="","",SUMIFS('Money Log'!$E$7:$E$506,'Money Log'!$D$7:$D$506,$B21,'Money Log'!$C$7:$C$506,"Expense",'Money Log'!$G$7:$G$506,F$5)) | G21: =IF($B21="","",SUMIFS('Money Log'!$E$7:$E$506,'Money Log'!$D$7:$D$506,$B21,'Money Log'!$C$7:$C$506,"Expense",'Money Log'!$G$7:$G$506,G$5)) | H21: =IF($B21="","",SUMIFS('Money Log'!$E$7:$E$506,'Money Log'!$D$7:$D$506,$B21,'Money Log'!$C$7:$C$506,"Expense",'Money Log'!$G$7:$G$506,H$5)) | I21: =IF($B21="","",SUMIFS('Money Log'!$E$7:$E$506,'Money Log'!$D$7:$D$506,$B21,'Money Log'!$C$7:$C$506,"Expense",'Money Log'!$G$7:$G$506,I$5)) | J21: =IF($B21="","",SUMIFS('Money Log'!$E$7:$E$506,'Money Log'!$D$7:$D$506,$B21,'Money Log'!$C$7:$C$506,"Expense",'Money Log'!$G$7:$G$506,J$5)) | ... N21: =IF($B21="","",SUMIFS('Money Log'!$E$7:$E$506,'Money Log'!$D$7:$D$506,$B21,'Money Log'!$C$7:$C$506,"Expense",'Money Log'!$G$7:$G$506,N$5)) | O21: =IF($B21="","",SUM(C21:N21))
B22: =IF('Setup'!E13="","",'Setup'!E13) | C22: =IF($B22="","",SUMIFS('Money Log'!$E$7:$E$506,'Money Log'!$D$7:$D$506,$B22,'Money Log'!$C$7:$C$506,"Expense",'Money Log'!$G$7:$G$506,C$5)) | D22: =IF($B22="","",SUMIFS('Money Log'!$E$7:$E$506,'Money Log'!$D$7:$D$506,$B22,'Money Log'!$C$7:$C$506,"Expense",'Money Log'!$G$7:$G$506,D$5)) | E22: =IF($B22="","",SUMIFS('Money Log'!$E$7:$E$506,'Money Log'!$D$7:$D$506,$B22,'Money Log'!$C$7:$C$506,"Expense",'Money Log'!$G$7:$G$506,E$5)) | F22: =IF($B22="","",SUMIFS('Money Log'!$E$7:$E$506,'Money Log'!$D$7:$D$506,$B22,'Money Log'!$C$7:$C$506,"Expense",'Money Log'!$G$7:$G$506,F$5)) | G22: =IF($B22="","",SUMIFS('Money Log'!$E$7:$E$506,'Money Log'!$D$7:$D$506,$B22,'Money Log'!$C$7:$C$506,"Expense",'Money Log'!$G$7:$G$506,G$5)) | H22: =IF($B22="","",SUMIFS('Money Log'!$E$7:$E$506,'Money Log'!$D$7:$D$506,$B22,'Money Log'!$C$7:$C$506,"Expense",'Money Log'!$G$7:$G$506,H$5)) | I22: =IF($B22="","",SUMIFS('Money Log'!$E$7:$E$506,'Money Log'!$D$7:$D$506,$B22,'Money Log'!$C$7:$C$506,"Expense",'Money Log'!$G$7:$G$506,I$5)) | J22: =IF($B22="","",SUMIFS('Money Log'!$E$7:$E$506,'Money Log'!$D$7:$D$506,$B22,'Money Log'!$C$7:$C$506,"Expense",'Money Log'!$G$7:$G$506,J$5)) | ... N22: =IF($B22="","",SUMIFS('Money Log'!$E$7:$E$506,'Money Log'!$D$7:$D$506,$B22,'Money Log'!$C$7:$C$506,"Expense",'Money Log'!$G$7:$G$506,N$5)) | O22: =IF($B22="","",SUM(C22:N22))
B23: =IF('Setup'!E14="","",'Setup'!E14) | C23: =IF($B23="","",SUMIFS('Money Log'!$E$7:$E$506,'Money Log'!$D$7:$D$506,$B23,'Money Log'!$C$7:$C$506,"Expense",'Money Log'!$G$7:$G$506,C$5)) | D23: =IF($B23="","",SUMIFS('Money Log'!$E$7:$E$506,'Money Log'!$D$7:$D$506,$B23,'Money Log'!$C$7:$C$506,"Expense",'Money Log'!$G$7:$G$506,D$5)) | E23: =IF($B23="","",SUMIFS('Money Log'!$E$7:$E$506,'Money Log'!$D$7:$D$506,$B23,'Money Log'!$C$7:$C$506,"Expense",'Money Log'!$G$7:$G$506,E$5)) | F23: =IF($B23="","",SUMIFS('Money Log'!$E$7:$E$506,'Money Log'!$D$7:$D$506,$B23,'Money Log'!$C$7:$C$506,"Expense",'Money Log'!$G$7:$G$506,F$5)) | G23: =IF($B23="","",SUMIFS('Money Log'!$E$7:$E$506,'Money Log'!$D$7:$D$506,$B23,'Money Log'!$C$7:$C$506,"Expense",'Money Log'!$G$7:$G$506,G$5)) | H23: =IF($B23="","",SUMIFS('Money Log'!$E$7:$E$506,'Money Log'!$D$7:$D$506,$B23,'Money Log'!$C$7:$C$506,"Expense",'Money Log'!$G$7:$G$506,H$5)) | I23: =IF($B23="","",SUMIFS('Money Log'!$E$7:$E$506,'Money Log'!$D$7:$D$506,$B23,'Money Log'!$C$7:$C$506,"Expense",'Money Log'!$G$7:$G$506,I$5)) | J23: =IF($B23="","",SUMIFS('Money Log'!$E$7:$E$506,'Money Log'!$D$7:$D$506,$B23,'Money Log'!$C$7:$C$506,"Expense",'Money Log'!$G$7:$G$506,J$5)) | ... N23: =IF($B23="","",SUMIFS('Money Log'!$E$7:$E$506,'Money Log'!$D$7:$D$506,$B23,'Money Log'!$C$7:$C$506,"Expense",'Money Log'!$G$7:$G$506,N$5)) | O23: =IF($B23="","",SUM(C23:N23))
B24: =IF('Setup'!E15="","",'Setup'!E15) | C24: =IF($B24="","",SUMIFS('Money Log'!$E$7:$E$506,'Money Log'!$D$7:$D$506,$B24,'Money Log'!$C$7:$C$506,"Expense",'Money Log'!$G$7:$G$506,C$5)) | D24: =IF($B24="","",SUMIFS('Money Log'!$E$7:$E$506,'Money Log'!$D$7:$D$506,$B24,'Money Log'!$C$7:$C$506,"Expense",'Money Log'!$G$7:$G$506,D$5)) | E24: =IF($B24="","",SUMIFS('Money Log'!$E$7:$E$506,'Money Log'!$D$7:$D$506,$B24,'Money Log'!$C$7:$C$506,"Expense",'Money Log'!$G$7:$G$506,E$5)) | F24: =IF($B24="","",SUMIFS('Money Log'!$E$7:$E$506,'Money Log'!$D$7:$D$506,$B24,'Money Log'!$C$7:$C$506,"Expense",'Money Log'!$G$7:$G$506,F$5)) | G24: =IF($B24="","",SUMIFS('Money Log'!$E$7:$E$506,'Money Log'!$D$7:$D$506,$B24,'Money Log'!$C$7:$C$506,"Expense",'Money Log'!$G$7:$G$506,G$5)) | H24: =IF($B24="","",SUMIFS('Money Log'!$E$7:$E$506,'Money Log'!$D$7:$D$506,$B24,'Money Log'!$C$7:$C$506,"Expense",'Money Log'!$G$7:$G$506,H$5)) | I24: =IF($B24="","",SUMIFS('Money Log'!$E$7:$E$506,'Money Log'!$D$7:$D$506,$B24,'Money Log'!$C$7:$C$506,"Expense",'Money Log'!$G$7:$G$506,I$5)) | J24: =IF($B24="","",SUMIFS('Money Log'!$E$7:$E$506,'Money Log'!$D$7:$D$506,$B24,'Money Log'!$C$7:$C$506,"Expense",'Money Log'!$G$7:$G$506,J$5)) | ... N24: =IF($B24="","",SUMIFS('Money Log'!$E$7:$E$506,'Money Log'!$D$7:$D$506,$B24,'Money Log'!$C$7:$C$506,"Expense",'Money Log'!$G$7:$G$506,N$5)) | O24: =IF($B24="","",SUM(C24:N24))
B25: =IF('Setup'!E16="","",'Setup'!E16) | C25: =IF($B25="","",SUMIFS('Money Log'!$E$7:$E$506,'Money Log'!$D$7:$D$506,$B25,'Money Log'!$C$7:$C$506,"Expense",'Money Log'!$G$7:$G$506,C$5)) | D25: =IF($B25="","",SUMIFS('Money Log'!$E$7:$E$506,'Money Log'!$D$7:$D$506,$B25,'Money Log'!$C$7:$C$506,"Expense",'Money Log'!$G$7:$G$506,D$5)) | E25: =IF($B25="","",SUMIFS('Money Log'!$E$7:$E$506,'Money Log'!$D$7:$D$506,$B25,'Money Log'!$C$7:$C$506,"Expense",'Money Log'!$G$7:$G$506,E$5)) | F25: =IF($B25="","",SUMIFS('Money Log'!$E$7:$E$506,'Money Log'!$D$7:$D$506,$B25,'Money Log'!$C$7:$C$506,"Expense",'Money Log'!$G$7:$G$506,F$5)) | G25: =IF($B25="","",SUMIFS('Money Log'!$E$7:$E$506,'Money Log'!$D$7:$D$506,$B25,'Money Log'!$C$7:$C$506,"Expense",'Money Log'!$G$7:$G$506,G$5)) | H25: =IF($B25="","",SUMIFS('Money Log'!$E$7:$E$506,'Money Log'!$D$7:$D$506,$B25,'Money Log'!$C$7:$C$506,"Expense",'Money Log'!$G$7:$G$506,H$5)) | I25: =IF($B25="","",SUMIFS('Money Log'!$E$7:$E$506,'Money Log'!$D$7:$D$506,$B25,'Money Log'!$C$7:$C$506,"Expense",'Money Log'!$G$7:$G$506,I$5)) | J25: =IF($B25="","",SUMIFS('Money Log'!$E$7:$E$506,'Money Log'!$D$7:$D$506,$B25,'Money Log'!$C$7:$C$506,"Expense",'Money Log'!$G$7:$G$506,J$5)) | ... N25: =IF($B25="","",SUMIFS('Money Log'!$E$7:$E$506,'Money Log'!$D$7:$D$506,$B25,'Money Log'!$C$7:$C$506,"Expense",'Money Log'!$G$7:$G$506,N$5)) | O25: =IF($B25="","",SUM(C25:N25))
B26: =IF('Setup'!E17="","",'Setup'!E17) | C26: =IF($B26="","",SUMIFS('Money Log'!$E$7:$E$506,'Money Log'!$D$7:$D$506,$B26,'Money Log'!$C$7:$C$506,"Expense",'Money Log'!$G$7:$G$506,C$5)) | D26: =IF($B26="","",SUMIFS('Money Log'!$E$7:$E$506,'Money Log'!$D$7:$D$506,$B26,'Money Log'!$C$7:$C$506,"Expense",'Money Log'!$G$7:$G$506,D$5)) | E26: =IF($B26="","",SUMIFS('Money Log'!$E$7:$E$506,'Money Log'!$D$7:$D$506,$B26,'Money Log'!$C$7:$C$506,"Expense",'Money Log'!$G$7:$G$506,E$5)) | F26: =IF($B26="","",SUMIFS('Money Log'!$E$7:$E$506,'Money Log'!$D$7:$D$506,$B26,'Money Log'!$C$7:$C$506,"Expense",'Money Log'!$G$7:$G$506,F$5)) | G26: =IF($B26="","",SUMIFS('Money Log'!$E$7:$E$506,'Money Log'!$D$7:$D$506,$B26,'Money Log'!$C$7:$C$506,"Expense",'Money Log'!$G$7:$G$506,G$5)) | H26: =IF($B26="","",SUMIFS('Money Log'!$E$7:$E$506,'Money Log'!$D$7:$D$506,$B26,'Money Log'!$C$7:$C$506,"Expense",'Money Log'!$G$7:$G$506,H$5)) | I26: =IF($B26="","",SUMIFS('Money Log'!$E$7:$E$506,'Money Log'!$D$7:$D$506,$B26,'Money Log'!$C$7:$C$506,"Expense",'Money Log'!$G$7:$G$506,I$5)) | J26: =IF($B26="","",SUMIFS('Money Log'!$E$7:$E$506,'Money Log'!$D$7:$D$506,$B26,'Money Log'!$C$7:$C$506,"Expense",'Money Log'!$G$7:$G$506,J$5)) | ... N26: =IF($B26="","",SUMIFS('Money Log'!$E$7:$E$506,'Money Log'!$D$7:$D$506,$B26,'Money Log'!$C$7:$C$506,"Expense",'Money Log'!$G$7:$G$506,N$5)) | O26: =IF($B26="","",SUM(C26:N26))
B27: =IF('Setup'!E18="","",'Setup'!E18) | C27: =IF($B27="","",SUMIFS('Money Log'!$E$7:$E$506,'Money Log'!$D$7:$D$506,$B27,'Money Log'!$C$7:$C$506,"Expense",'Money Log'!$G$7:$G$506,C$5)) | D27: =IF($B27="","",SUMIFS('Money Log'!$E$7:$E$506,'Money Log'!$D$7:$D$506,$B27,'Money Log'!$C$7:$C$506,"Expense",'Money Log'!$G$7:$G$506,D$5)) | E27: =IF($B27="","",SUMIFS('Money Log'!$E$7:$E$506,'Money Log'!$D$7:$D$506,$B27,'Money Log'!$C$7:$C$506,"Expense",'Money Log'!$G$7:$G$506,E$5)) | F27: =IF($B27="","",SUMIFS('Money Log'!$E$7:$E$506,'Money Log'!$D$7:$D$506,$B27,'Money Log'!$C$7:$C$506,"Expense",'Money Log'!$G$7:$G$506,F$5)) | G27: =IF($B27="","",SUMIFS('Money Log'!$E$7:$E$506,'Money Log'!$D$7:$D$506,$B27,'Money Log'!$C$7:$C$506,"Expense",'Money Log'!$G$7:$G$506,G$5)) | H27: =IF($B27="","",SUMIFS('Money Log'!$E$7:$E$506,'Money Log'!$D$7:$D$506,$B27,'Money Log'!$C$7:$C$506,"Expense",'Money Log'!$G$7:$G$506,H$5)) | I27: =IF($B27="","",SUMIFS('Money Log'!$E$7:$E$506,'Money Log'!$D$7:$D$506,$B27,'Money Log'!$C$7:$C$506,"Expense",'Money Log'!$G$7:$G$506,I$5)) | J27: =IF($B27="","",SUMIFS('Money Log'!$E$7:$E$506,'Money Log'!$D$7:$D$506,$B27,'Money Log'!$C$7:$C$506,"Expense",'Money Log'!$G$7:$G$506,J$5)) | ... N27: =IF($B27="","",SUMIFS('Money Log'!$E$7:$E$506,'Money Log'!$D$7:$D$506,$B27,'Money Log'!$C$7:$C$506,"Expense",'Money Log'!$G$7:$G$506,N$5)) | O27: =IF($B27="","",SUM(C27:N27))
B28: =IF('Setup'!E19="","",'Setup'!E19) | C28: =IF($B28="","",SUMIFS('Money Log'!$E$7:$E$506,'Money Log'!$D$7:$D$506,$B28,'Money Log'!$C$7:$C$506,"Expense",'Money Log'!$G$7:$G$506,C$5)) | D28: =IF($B28="","",SUMIFS('Money Log'!$E$7:$E$506,'Money Log'!$D$7:$D$506,$B28,'Money Log'!$C$7:$C$506,"Expense",'Money Log'!$G$7:$G$506,D$5)) | E28: =IF($B28="","",SUMIFS('Money Log'!$E$7:$E$506,'Money Log'!$D$7:$D$506,$B28,'Money Log'!$C$7:$C$506,"Expense",'Money Log'!$G$7:$G$506,E$5)) | F28: =IF($B28="","",SUMIFS('Money Log'!$E$7:$E$506,'Money Log'!$D$7:$D$506,$B28,'Money Log'!$C$7:$C$506,"Expense",'Money Log'!$G$7:$G$506,F$5)) | G28: =IF($B28="","",SUMIFS('Money Log'!$E$7:$E$506,'Money Log'!$D$7:$D$506,$B28,'Money Log'!$C$7:$C$506,"Expense",'Money Log'!$G$7:$G$506,G$5)) | H28: =IF($B28="","",SUMIFS('Money Log'!$E$7:$E$506,'Money Log'!$D$7:$D$506,$B28,'Money Log'!$C$7:$C$506,"Expense",'Money Log'!$G$7:$G$506,H$5)) | I28: =IF($B28="","",SUMIFS('Money Log'!$E$7:$E$506,'Money Log'!$D$7:$D$506,$B28,'Money Log'!$C$7:$C$506,"Expense",'Money Log'!$G$7:$G$506,I$5)) | J28: =IF($B28="","",SUMIFS('Money Log'!$E$7:$E$506,'Money Log'!$D$7:$D$506,$B28,'Money Log'!$C$7:$C$506,"Expense",'Money Log'!$G$7:$G$506,J$5)) | ... N28: =IF($B28="","",SUMIFS('Money Log'!$E$7:$E$506,'Money Log'!$D$7:$D$506,$B28,'Money Log'!$C$7:$C$506,"Expense",'Money Log'!$G$7:$G$506,N$5)) | O28: =IF($B28="","",SUM(C28:N28))
B29: =IF('Setup'!E20="","",'Setup'!E20) | C29: =IF($B29="","",SUMIFS('Money Log'!$E$7:$E$506,'Money Log'!$D$7:$D$506,$B29,'Money Log'!$C$7:$C$506,"Expense",'Money Log'!$G$7:$G$506,C$5)) | D29: =IF($B29="","",SUMIFS('Money Log'!$E$7:$E$506,'Money Log'!$D$7:$D$506,$B29,'Money Log'!$C$7:$C$506,"Expense",'Money Log'!$G$7:$G$506,D$5)) | E29: =IF($B29="","",SUMIFS('Money Log'!$E$7:$E$506,'Money Log'!$D$7:$D$506,$B29,'Money Log'!$C$7:$C$506,"Expense",'Money Log'!$G$7:$G$506,E$5)) | F29: =IF($B29="","",SUMIFS('Money Log'!$E$7:$E$506,'Money Log'!$D$7:$D$506,$B29,'Money Log'!$C$7:$C$506,"Expense",'Money Log'!$G$7:$G$506,F$5)) | G29: =IF($B29="","",SUMIFS('Money Log'!$E$7:$E$506,'Money Log'!$D$7:$D$506,$B29,'Money Log'!$C$7:$C$506,"Expense",'Money Log'!$G$7:$G$506,G$5)) | H29: =IF($B29="","",SUMIFS('Money Log'!$E$7:$E$506,'Money Log'!$D$7:$D$506,$B29,'Money Log'!$C$7:$C$506,"Expense",'Money Log'!$G$7:$G$506,H$5)) | I29: =IF($B29="","",SUMIFS('Money Log'!$E$7:$E$506,'Money Log'!$D$7:$D$506,$B29,'Money Log'!$C$7:$C$506,"Expense",'Money Log'!$G$7:$G$506,I$5)) | J29: =IF($B29="","",SUMIFS('Money Log'!$E$7:$E$506,'Money Log'!$D$7:$D$506,$B29,'Money Log'!$C$7:$C$506,"Expense",'Money Log'!$G$7:$G$506,J$5)) | ... N29: =IF($B29="","",SUMIFS('Money Log'!$E$7:$E$506,'Money Log'!$D$7:$D$506,$B29,'Money Log'!$C$7:$C$506,"Expense",'Money Log'!$G$7:$G$506,N$5)) | O29: =IF($B29="","",SUM(C29:N29))
B30: =IF('Setup'!E21="","",'Setup'!E21) | C30: =IF($B30="","",SUMIFS('Money Log'!$E$7:$E$506,'Money Log'!$D$7:$D$506,$B30,'Money Log'!$C$7:$C$506,"Expense",'Money Log'!$G$7:$G$506,C$5)) | D30: =IF($B30="","",SUMIFS('Money Log'!$E$7:$E$506,'Money Log'!$D$7:$D$506,$B30,'Money Log'!$C$7:$C$506,"Expense",'Money Log'!$G$7:$G$506,D$5)) | E30: =IF($B30="","",SUMIFS('Money Log'!$E$7:$E$506,'Money Log'!$D$7:$D$506,$B30,'Money Log'!$C$7:$C$506,"Expense",'Money Log'!$G$7:$G$506,E$5)) | F30: =IF($B30="","",SUMIFS('Money Log'!$E$7:$E$506,'Money Log'!$D$7:$D$506,$B30,'Money Log'!$C$7:$C$506,"Expense",'Money Log'!$G$7:$G$506,F$5)) | G30: =IF($B30="","",SUMIFS('Money Log'!$E$7:$E$506,'Money Log'!$D$7:$D$506,$B30,'Money Log'!$C$7:$C$506,"Expense",'Money Log'!$G$7:$G$506,G$5)) | H30: =IF($B30="","",SUMIFS('Money Log'!$E$7:$E$506,'Money Log'!$D$7:$D$506,$B30,'Money Log'!$C$7:$C$506,"Expense",'Money Log'!$G$7:$G$506,H$5)) | I30: =IF($B30="","",SUMIFS('Money Log'!$E$7:$E$506,'Money Log'!$D$7:$D$506,$B30,'Money Log'!$C$7:$C$506,"Expense",'Money Log'!$G$7:$G$506,I$5)) | J30: =IF($B30="","",SUMIFS('Money Log'!$E$7:$E$506,'Money Log'!$D$7:$D$506,$B30,'Money Log'!$C$7:$C$506,"Expense",'Money Log'!$G$7:$G$506,J$5)) | ... N30: =IF($B30="","",SUMIFS('Money Log'!$E$7:$E$506,'Money Log'!$D$7:$D$506,$B30,'Money Log'!$C$7:$C$506,"Expense",'Money Log'!$G$7:$G$506,N$5)) | O30: =IF($B30="","",SUM(C30:N30))
B31: =IF('Setup'!E22="","",'Setup'!E22) | C31: =IF($B31="","",SUMIFS('Money Log'!$E$7:$E$506,'Money Log'!$D$7:$D$506,$B31,'Money Log'!$C$7:$C$506,"Expense",'Money Log'!$G$7:$G$506,C$5)) | D31: =IF($B31="","",SUMIFS('Money Log'!$E$7:$E$506,'Money Log'!$D$7:$D$506,$B31,'Money Log'!$C$7:$C$506,"Expense",'Money Log'!$G$7:$G$506,D$5)) | E31: =IF($B31="","",SUMIFS('Money Log'!$E$7:$E$506,'Money Log'!$D$7:$D$506,$B31,'Money Log'!$C$7:$C$506,"Expense",'Money Log'!$G$7:$G$506,E$5)) | F31: =IF($B31="","",SUMIFS('Money Log'!$E$7:$E$506,'Money Log'!$D$7:$D$506,$B31,'Money Log'!$C$7:$C$506,"Expense",'Money Log'!$G$7:$G$506,F$5)) | G31: =IF($B31="","",SUMIFS('Money Log'!$E$7:$E$506,'Money Log'!$D$7:$D$506,$B31,'Money Log'!$C$7:$C$506,"Expense",'Money Log'!$G$7:$G$506,G$5)) | H31: =IF($B31="","",SUMIFS('Money Log'!$E$7:$E$506,'Money Log'!$D$7:$D$506,$B31,'Money Log'!$C$7:$C$506,"Expense",'Money Log'!$G$7:$G$506,H$5)) | I31: =IF($B31="","",SUMIFS('Money Log'!$E$7:$E$506,'Money Log'!$D$7:$D$506,$B31,'Money Log'!$C$7:$C$506,"Expense",'Money Log'!$G$7:$G$506,I$5)) | J31: =IF($B31="","",SUMIFS('Money Log'!$E$7:$E$506,'Money Log'!$D$7:$D$506,$B31,'Money Log'!$C$7:$C$506,"Expense",'Money Log'!$G$7:$G$506,J$5)) | ... N31: =IF($B31="","",SUMIFS('Money Log'!$E$7:$E$506,'Money Log'!$D$7:$D$506,$B31,'Money Log'!$C$7:$C$506,"Expense",'Money Log'!$G$7:$G$506,N$5)) | O31: =IF($B31="","",SUM(C31:N31))
B32: =IF('Setup'!E23="","",'Setup'!E23) | C32: =IF($B32="","",SUMIFS('Money Log'!$E$7:$E$506,'Money Log'!$D$7:$D$506,$B32,'Money Log'!$C$7:$C$506,"Expense",'Money Log'!$G$7:$G$506,C$5)) | D32: =IF($B32="","",SUMIFS('Money Log'!$E$7:$E$506,'Money Log'!$D$7:$D$506,$B32,'Money Log'!$C$7:$C$506,"Expense",'Money Log'!$G$7:$G$506,D$5)) | E32: =IF($B32="","",SUMIFS('Money Log'!$E$7:$E$506,'Money Log'!$D$7:$D$506,$B32,'Money Log'!$C$7:$C$506,"Expense",'Money Log'!$G$7:$G$506,E$5)) | F32: =IF($B32="","",SUMIFS('Money Log'!$E$7:$E$506,'Money Log'!$D$7:$D$506,$B32,'Money Log'!$C$7:$C$506,"Expense",'Money Log'!$G$7:$G$506,F$5)) | G32: =IF($B32="","",SUMIFS('Money Log'!$E$7:$E$506,'Money Log'!$D$7:$D$506,$B32,'Money Log'!$C$7:$C$506,"Expense",'Money Log'!$G$7:$G$506,G$5)) | H32: =IF($B32="","",SUMIFS('Money Log'!$E$7:$E$506,'Money Log'!$D$7:$D$506,$B32,'Money Log'!$C$7:$C$506,"Expense",'Money Log'!$G$7:$G$506,H$5)) | I32: =IF($B32="","",SUMIFS('Money Log'!$E$7:$E$506,'Money Log'!$D$7:$D$506,$B32,'Money Log'!$C$7:$C$506,"Expense",'Money Log'!$G$7:$G$506,I$5)) | J32: =IF($B32="","",SUMIFS('Money Log'!$E$7:$E$506,'Money Log'!$D$7:$D$506,$B32,'Money Log'!$C$7:$C$506,"Expense",'Money Log'!$G$7:$G$506,J$5)) | ... N32: =IF($B32="","",SUMIFS('Money Log'!$E$7:$E$506,'Money Log'!$D$7:$D$506,$B32,'Money Log'!$C$7:$C$506,"Expense",'Money Log'!$G$7:$G$506,N$5)) | O32: =IF($B32="","",SUM(C32:N32))
... B40: =IF('Setup'!E31="","",'Setup'!E31) | C40: =IF($B40="","",SUMIFS('Money Log'!$E$7:$E$506,'Money Log'!$D$7:$D$506,$B40,'Money Log'!$C$7:$C$506,"Expense",'Money Log'!$G$7:$G$506,C$5)) | D40: =IF($B40="","",SUMIFS('Money Log'!$E$7:$E$506,'Money Log'!$D$7:$D$506,$B40,'Money Log'!$C$7:$C$506,"Expense",'Money Log'!$G$7:$G$506,D$5)) | E40: =IF($B40="","",SUMIFS('Money Log'!$E$7:$E$506,'Money Log'!$D$7:$D$506,$B40,'Money Log'!$C$7:$C$506,"Expense",'Money Log'!$G$7:$G$506,E$5)) | F40: =IF($B40="","",SUMIFS('Money Log'!$E$7:$E$506,'Money Log'!$D$7:$D$506,$B40,'Money Log'!$C$7:$C$506,"Expense",'Money Log'!$G$7:$G$506,F$5)) | G40: =IF($B40="","",SUMIFS('Money Log'!$E$7:$E$506,'Money Log'!$D$7:$D$506,$B40,'Money Log'!$C$7:$C$506,"Expense",'Money Log'!$G$7:$G$506,G$5)) | H40: =IF($B40="","",SUMIFS('Money Log'!$E$7:$E$506,'Money Log'!$D$7:$D$506,$B40,'Money Log'!$C$7:$C$506,"Expense",'Money Log'!$G$7:$G$506,H$5)) | I40: =IF($B40="","",SUMIFS('Money Log'!$E$7:$E$506,'Money Log'!$D$7:$D$506,$B40,'Money Log'!$C$7:$C$506,"Expense",'Money Log'!$G$7:$G$506,I$5)) | J40: =IF($B40="","",SUMIFS('Money Log'!$E$7:$E$506,'Money Log'!$D$7:$D$506,$B40,'Money Log'!$C$7:$C$506,"Expense",'Money Log'!$G$7:$G$506,J$5)) | ... N40: =IF($B40="","",SUMIFS('Money Log'!$E$7:$E$506,'Money Log'!$D$7:$D$506,$B40,'Money Log'!$C$7:$C$506,"Expense",'Money Log'!$G$7:$G$506,N$5)) | O40: =IF($B40="","",SUM(C40:N40))
B41: Total expense | C41: =SUM(C21:C40) | D41: =SUM(D21:D40) | E41: =SUM(E21:E40) | F41: =SUM(F21:F40) | G41: =SUM(G21:G40) | H41: =SUM(H21:H40) | I41: =SUM(I21:I40) | J41: =SUM(J21:J40) | ... O41: =SUM(O21:O40)
B43: Net (income − expenses) | C43: =C18-C41 | D43: =D18-D41 | E43: =E18-E41 | F43: =F18-F41 | G43: =G18-G41 | H43: =H18-H41 | I43: =I18-I41 | J43: =J18-J41 | ... O43: =O18-O41

Sheet Savings & Debt
B2: Savings & Debt
B3: Type targets, balances and amounts saved or paid. Progress fills itself.
B6: Savings goal | C6: Target | D6: Saved | E6: Still needed | F6: Progress | G6: Target date
B7: Emergency fund | C7: 5000 | D7: 2100 | E7: =IF(B7="","",MAX(0,N(C7)-N(D7))) | F7: =IF(OR(B7="",N(C7)=0),"",MIN(1,N(D7)/C7)) | G7: 46568
B8: Vacation | C8: 1800 | D8: 650 | E8: =IF(B8="","",MAX(0,N(C8)-N(D8))) | F8: =IF(OR(B8="",N(C8)=0),"",MIN(1,N(D8)/C8)) | G8: 46569
B9: New laptop | C9: 1200 | D9: 900 | E9: =IF(B9="","",MAX(0,N(C9)-N(D9))) | F9: =IF(OR(B9="",N(C9)=0),"",MIN(1,N(D9)/C9)) | G9: 46418
B10: Car repairs | C10: 800 | D10: 240 | E10: =IF(B10="","",MAX(0,N(C10)-N(D10))) | F10: =IF(OR(B10="",N(C10)=0),"",MIN(1,N(D10)/C10))
E11: =IF(B11="","",MAX(0,N(C11)-N(D11))) | F11: =IF(OR(B11="",N(C11)=0),"",MIN(1,N(D11)/C11))
E12: =IF(B12="","",MAX(0,N(C12)-N(D12))) | F12: =IF(OR(B12="",N(C12)=0),"",MIN(1,N(D12)/C12))
E13: =IF(B13="","",MAX(0,N(C13)-N(D13))) | F13: =IF(OR(B13="",N(C13)=0),"",MIN(1,N(D13)/C13))
E14: =IF(B14="","",MAX(0,N(C14)-N(D14))) | F14: =IF(OR(B14="",N(C14)=0),"",MIN(1,N(D14)/C14))
E15: =IF(B15="","",MAX(0,N(C15)-N(D15))) | F15: =IF(OR(B15="",N(C15)=0),"",MIN(1,N(D15)/C15))
E16: =IF(B16="","",MAX(0,N(C16)-N(D16))) | F16: =IF(OR(B16="",N(C16)=0),"",MIN(1,N(D16)/C16))
E17: =IF(B17="","",MAX(0,N(C17)-N(D17))) | F17: =IF(OR(B17="",N(C17)=0),"",MIN(1,N(D17)/C17))
E18: =IF(B18="","",MAX(0,N(C18)-N(D18))) | F18: =IF(OR(B18="",N(C18)=0),"",MIN(1,N(D18)/C18))
B21: Debt | C21: Starting balance | D21: Paid so far | E21: Remaining | F21: Paid off | G21: Min. payment
B22: Credit card | C22: 3200 | D22: 1150 | E22: =IF(B22="","",MAX(0,N(C22)-N(D22))) | F22: =IF(OR(B22="",N(C22)=0),"",MIN(1,N(D22)/C22)) | G22: 90
B23: Car loan | C23: 9800 | D23: 2600 | E23: =IF(B23="","",MAX(0,N(C23)-N(D23))) | F23: =IF(OR(B23="",N(C23)=0),"",MIN(1,N(D23)/C23)) | G23: 245
B24: Student loan | C24: 14500 | D24: 1800 | E24: =IF(B24="","",MAX(0,N(C24)-N(D24))) | F24: =IF(OR(B24="",N(C24)=0),"",MIN(1,N(D24)/C24)) | G24: 160
E25: =IF(B25="","",MAX(0,N(C25)-N(D25))) | F25: =IF(OR(B25="",N(C25)=0),"",MIN(1,N(D25)/C25))
E26: =IF(B26="","",MAX(0,N(C26)-N(D26))) | F26: =IF(OR(B26="",N(C26)=0),"",MIN(1,N(D26)/C26))
E27: =IF(B27="","",MAX(0,N(C27)-N(D27))) | F27: =IF(OR(B27="",N(C27)=0),"",MIN(1,N(D27)/C27))
E28: =IF(B28="","",MAX(0,N(C28)-N(D28))) | F28: =IF(OR(B28="",N(C28)=0),"",MIN(1,N(D28)/C28))
E29: =IF(B29="","",MAX(0,N(C29)-N(D29))) | F29: =IF(OR(B29="",N(C29)=0),"",MIN(1,N(D29)/C29))
E30: =IF(B30="","",MAX(0,N(C30)-N(D30))) | F30: =IF(OR(B30="",N(C30)=0),"",MIN(1,N(D30)/C30))
E31: =IF(B31="","",MAX(0,N(C31)-N(D31))) | F31: =IF(OR(B31="",N(C31)=0),"",MIN(1,N(D31)/C31))
E32: =IF(B32="","",MAX(0,N(C32)-N(D32))) | F32: =IF(OR(B32="",N(C32)=0),"",MIN(1,N(D32)/C32))
E33: =IF(B33="","",MAX(0,N(C33)-N(D33))) | F33: =IF(OR(B33="",N(C33)=0),"",MIN(1,N(D33)/C33))
B36: Total saved | C36: =SUM(D7:D18)
B37: Total debt remaining | C37: =SUM(E22:E33)
B38: Monthly minimum payments | C38: =SUM(G22:G33)

Sheet Tasks
B2: Task List
B3: Type a task, pick a category, a due date and a priority. Mark it Done when finished.
B6: Task | C6: Category | D6: Due date | E6: Priority | F6: Status | G6: Days left
B7: Pay car insurance | C7: Money | D7: 46309 | E7: High | F7: To do | G7: =IF(OR(B7="",D7="",F7="Done"),"",D7-TODAY()) | I7: =IF(OR(B7="",D7="",F7="Done"),"",D7+ROW()/100000)
B8: Book dentist check-up | C8: Health | D8: 46312 | E8: Medium | F8: To do | G8: =IF(OR(B8="",D8="",F8="Done"),"",D8-TODAY()) | I8: =IF(OR(B8="",D8="",F8="Done"),"",D8+ROW()/100000)
B9: Renew passport | C9: Personal | D9: 46325 | E9: Medium | F9: In progress | G9: =IF(OR(B9="",D9="",F9="Done"),"",D9-TODAY()) | I9: =IF(OR(B9="",D9="",F9="Done"),"",D9+ROW()/100000)
